<?xml version="1.0"?>
<robot name="mickrobot" xmlns:xacro="http://www.ros.org/wiki/xacro">
  <link name="base_link">
    <visual>
      <geometry>
        <box size="0.25 .16 .05"/>
    </geometry>
    <origin rpy="0 0 0" xyz="0 0 0.0"/>
    <material name="gree">
        <color rgba="0 0 .8 1"/>
    </material>
    </visual>
  </link>
 
  <xacro:macro name="wheel_link" params="wheel_name xyz">
	 <link name="${wheel_name}_link">
	    <visual>
	      <geometry>
		<cylinder length=".02" radius="0.05"/>
	      </geometry>
	      <material name="red">
		<color rgba="1 0 0 1"/>
	      </material>
	    </visual>
	  </link>

	  <joint name="${wheel_name}_joint" type="continuous">
	    <axis xyz="0 0 1"/>
	    <parent link="base_link"/>
	    <child link="${wheel_name}_link"/>
	    <origin rpy="1.57075 0 0" xyz="${xyz}"/>
	    <limit effort="100" velocity="100"/>
	    <joint_properties damping="0.0" friction="0.0"/>
	  </joint>
  </xacro:macro>
 
  <xacro:wheel_link wheel_name = "left_front_wheel" xyz="0.12 0.1 0"/>
  <xacro:wheel_link wheel_name = "right_front_wheel" xyz="0.12 -0.1 0"/>
  <xacro:wheel_link wheel_name = "right_back_wheel" xyz="-0.12 -0.1 0"/>
  <xacro:wheel_link wheel_name = "left_back_wheel" xyz="-0.12 0.1 0"/>
 

  <link name="camera">
    <visual>
      <geometry>
        <box size=".02 .03 .03"/>
      </geometry>
      <material name="white">
          <color rgba="1 1 1 1"/>
      </material>
    </visual>
  </link>

  <joint name="camera_joint" type="fixed">
    <parent link="base_link"/>
    <child link="camera"/>
    <origin xyz="0.1 0.0 0.025"/>
  </joint>
  
</robot>

