<?xml version="1.0"?>
<robot name="mickrobot" xmlns:xacro="http://ros.org/wiki/xacro">

  <!-- base -->
  <link name="base_link">
    <visual>
      <origin xyz="0.333 0.6 0" rpy="0 0 3.14159"/>
      <geometry>
        <mesh filename="/home/wyt/mickrobot_ws/src/mickrobot_description/urdf/mesh/mickx4_body.STL" scale="0.001 0.001 0.001"/>
      </geometry>
      <material name="Gray">
        <color rgba="0.5 0.5 0.5 1"/>
      </material>
    </visual>

    <collision>
      <origin xyz="0 0 0" rpy="0 0 0"/>
      <geometry>
        <box size="0.333 0.6 0.16"/>
      </geometry>
    </collision>

    <inertial>
      <mass value="25"/>
      <origin xyz="0.1665 0.3 0.08" rpy="0 0 1.57079"/>
      <inertia 
        ixx="0.284" ixy="0" ixz="0"  
        iyy="0.803" iyz="0"           
        izz="0.981"/>
    </inertial>
  </link>
  
  <!-- right_back_wheel -->
  <link   name="right_back_wheel">
    <visual>
      <origin xyz="0 -0.119 0.111" rpy="0 1.57079 0"/>
      <geometry>
        <mesh filename="/home/wyt/mickrobot_ws/src/mickrobot_description/urdf/mesh/mickx4_wheel_8inches2.STL" scale="0.001 0.001 0.001"/>
      </geometry>
    </visual>

    <collision>
      <origin xyz="0.03 0 0" rpy="0 1.57079 0"/>
      <geometry>
        <cylinder radius="0.1016" length="0.06"/>
      </geometry>
    </collision>
    
    <inertial>  
      <mass value="1"/>
      <origin xyz="0.03 0 0" rpy="0 1.57079 0"/>
      <inertia ixx="0.00288" ixy="0.0" ixz="0.0" iyy="0.00288" iyz="0.0" izz="0.00516"/>
    </inertial>
  </link>
 
  <joint   name="right_back_wheel_joint" type="continuous">
    <axis xyz="1 0 0"/>
    <parent   link="base_link"/>
    <child   link="right_back_wheel"/>
    <origin   xyz="0.36 0.1 0"/>
    <limit effort="100"   velocity="100"/>
  </joint>
  <!-- right_front_wheel -->
  
  <link   name="right_front_wheel">
    <visual>
      <origin xyz="0 -0.119 0.111" rpy="0 1.57079 0"/>
      <geometry>
        <mesh filename="/home/wyt/mickrobot_ws/src/mickrobot_description/urdf/mesh/mickx4_wheel_8inches2.STL" scale="0.001 0.001 0.001"/>
      </geometry>
    </visual>

    <collision>
      <origin xyz="0.03 0 0" rpy="0 1.57079 0"/>
      <geometry>
        <cylinder radius="0.1016" length="0.06"/>
      </geometry>
    </collision>
    
    <inertial>
      <mass value="1"/>
      <origin xyz="0.03 0 0" rpy="0 1.57079 0"/>
      <inertia ixx="0.00288" ixy="0.0" ixz="0.0" iyy="0.00288" iyz="0.0" izz="0.00516"/>
    </inertial>
  </link>
 
  <joint   name="right_front_wheel_joint" type="continuous">
    <axis xyz="1 0 0"/>
    <parent   link="base_link"/>
    <child   link="right_front_wheel"/>
    <origin   xyz="0.36 0.5 0"/>
    <limit effort="100"   velocity="100"/>
  </joint>
  
  <!-- left_back_wheel -->
  <link   name="left_back_wheel">
    <visual>
      <origin xyz="0 -0.119 -0.111" rpy="0 -1.57079 0"/>
      <geometry>
        <mesh filename="/home/wyt/mickrobot_ws/src/mickrobot_description/urdf/mesh/mickx4_wheel_8inches2.STL" scale="0.001 0.001 0.001"/>
      </geometry>
    </visual>

    <collision>
      <origin xyz="-0.03 0 0" rpy="0 -1.57079 0"/>
      <geometry>
        <cylinder radius="0.1016" length="0.06"/>
      </geometry>
    </collision>

  <inertial> 
    <mass value="1"/>
    <origin xyz="-0.03 0 0" rpy="0 -1.57079 0"/>
    <inertia ixx="0.00288" ixy="0.0" ixz="0.0" iyy="0.00288" iyz="0.0" izz="0.00516"/>
  </inertial>
  </link>
 
  <joint   name="left_back_wheel_joint" type="continuous">
    <axis xyz="1 0 0"/>
    <parent   link="base_link"/>
  <child   link="left_back_wheel"/>
    <origin   xyz="-0.027 0.1 0"/>
    <limit effort="100"   velocity="100"/>
  </joint>
  
  <!-- left_front_wheel -->
  <link   name="left_front_wheel">
    <visual>
      <origin xyz="0 -0.119 -0.111" rpy="0 -1.57079 0"/>
      <geometry>
        <mesh filename="/home/wyt/mickrobot_ws/src/mickrobot_description/urdf/mesh/mickx4_wheel_8inches2.STL" scale="0.001 0.001 0.001"/>
      </geometry>
    </visual>

    <collision>
      <origin xyz="-0.03 0 0" rpy="0 -1.57079 0"/>
      <geometry>
        <cylinder radius="0.1016" length="0.06"/>
      </geometry>
    </collision>

    <inertial>
      <mass value="1"/>
      <origin xyz="-0.03 0 0" rpy="0 -1.57079 0"/>
      <inertia ixx="0.00288" ixy="0.0" ixz="0.0" iyy="0.00288" iyz="0.0" izz="0.00516"/>
    </inertial>
  </link>
 
  <joint   name="left_front_wheel_joint" type="continuous">
    <axis xyz="1 0 0"/>   
    <parent   link="base_link"/>
    <child   link="left_front_wheel"/>
    <origin   xyz="-0.027 0.5 0"/>
    <limit effort="100"   velocity="100"/>
  </joint>
  
  <!-- sensor -->
  <link   name="sensor_link">
    <visual>
      <origin xyz="0 0 0" rpy="0 0 3.14159"/>
      <geometry>
        <mesh filename="/home/wyt/mickrobot_ws/src/mickrobot_description/urdf/mesh/mickx4_sensorkit.STL" scale="0.001 0.001 0.001"/>
      </geometry>
    </visual>

    <collision>
      <origin xyz="0 0 0" rpy="0 0 3.14159"/>
      <geometry>
        <mesh filename="/home/wyt/mickrobot_ws/src/mickrobot_description/urdf/mesh/mickx4_sensorkit.STL" scale="0.001 0.001 0.001"/>
      </geometry>
    </collision>

    <inertial>
      <mass value="1"/>
      <origin xyz="-0.12 -0.07 0.09" rpy="0 0 3.14159"/>
      <inertia ixx="0.00333" ixy="0.0" ixz="0.0" iyy="0.00333" iyz="0.0" izz="0.00240"/>
    </inertial>
  </link>
 
  <joint   name="sensor_joint" type="fixed">  
    <parent   link="base_link"/>
    <child   link="sensor_link"/>
    <origin   xyz="0.29 0.20 0.15"/>
  </joint>
  
  <!-- imu -->
  <link name="imu_link">
    <visual>
      <origin xyz="0 0 0.0" rpy="0 0 0"/>
      <geometry>
        <box size="0.02 0.02 0.02"/>
      </geometry>
    </visual>

    <collision>
      <origin xyz="0.0 0.0 0.0" rpy="0.0 0.0 0.0"/>
      <geometry>
        <box size="0.02 0.02 0.02"/>
      </geometry>
    </collision>

    <inertial>
      <origin xyz="0.0 0.0 0.0" rpy="0.0 0.0 0.0"/>
      <mass value="0.5"/>
      <inertia ixx="3.333e-5" ixy="0.0" ixz="0.0" iyy="3.333e-5" iyz="0.0" izz="3.333e-5"/>
    </inertial>
    </link>
  
  <joint name="imu_joint" type="fixed">
      <parent link="base_link" />
      <child link="imu_link" />
      <origin xyz="0.173 0.165 0.163" rpy="0.0 0.0 3.14159" />
  </joint>
  
  <!-- gnss -->
  <link name="gnss_link">
    <visual>
      <origin xyz="0 0 0.0" rpy="0 0 0"/>
      <geometry>
        <box size="0.02 0.02 0.02"/>
      </geometry>
    </visual>

    <collision>
      <origin xyz="0.0 0.0 0.0" rpy="0.0 0.0 0.0"/>
      <geometry>
        <box size="0.02 0.02 0.02"/>
      </geometry>
    </collision>

    <inertial>
      <origin xyz="0.0 0.0 0.0" rpy="0.0 0.0 0.0"/>
      <mass value="0.5"/>
      <inertia ixx="3.333e-5" ixy="0.0" ixz="0.0" iyy="3.333e-5" iyz="0.0" izz="3.333e-5"/>
    </inertial>
  </link>

  <joint name="gnss_joint" type="fixed">
    <parent link="base_link" />
    <child link="gnss_link" />
    <origin xyz="0.173 0.165 0.25" rpy="0.0 0.0 0.0" />
  </joint>

  <!-- laser -->
  <link name="laser_link">
    <visual>
      <origin xyz="0 0 0" rpy="0 0 0"/>
      <geometry>
        <cylinder length="0.05" radius="0.04"/>
      </geometry>
    </visual>

    <collision>
      <origin xyz="0 0 0" rpy="0 0 0"/>
      <geometry>
        <cylinder length="0.05" radius="0.04"/>
      </geometry>
    </collision>

    <inertial>
      <mass value="0.1"/>
      <inertia ixx="6.083e-5" ixy="0" ixz="0" iyy="6.083e-5" iyz="0" izz="8.0e-5"/>
    </inertial>
  </link>
  
  <joint name="laser_joint" type="fixed">
      <parent link="base_link" />
      <child link="laser_link" />
      <origin xyz="0.173 0.13 0.37" />
  </joint>
  
  <!-- camera -->
  <link name="camera_link">
    <visual>
      <origin xyz="0 0 0" rpy="0 0 0"/>
      <geometry>
        <box size="0.05 0.05 0.05"/>
      </geometry>
    </visual>
    
    <inertial>
      <mass value="0.1"/>
      <origin xyz="0 0 0" rpy="0 0 0"/>
      <inertia ixx="0.001" ixy="0" ixz="0" iyy="0.001" iyz="0" izz="0.001"/>
    </inertial>
       
    <collision>
      <origin xyz="0 0 0" rpy="0 0 0"/>
      <geometry>
        <box size="0.05 0.05 0.05"/>
      </geometry>
    </collision>
  </link>

  <joint name="camera_joint" type="fixed">
    <parent link="base_link"/>
    <child link="camera_link"/>
    <origin xyz="0.1665 0.025 0.15" rpy="0 0 -1.57079"/>
  </joint>

  <!-- diff_drive_plugin -->
  <gazebo>
    <plugin name='diff_drive' filename='libgazebo_ros_diff_drive.so'>
          <ros>
            <namespace>/</namespace>
            <remapping>cmd_vel:=cmd_vel</remapping>
            <remapping>odom:=odom</remapping>
          </ros>
          <update_rate>30</update_rate>
          <left_joint>right_front_wheel_joint</left_joint>
          <right_joint>left_front_wheel_joint</right_joint>
          <!-- kinematics -->
          <wheel_separation>0.447</wheel_separation>
          <wheel_diameter>0.2032</wheel_diameter>
          <!-- limits -->
          <max_wheel_torque>50</max_wheel_torque>
          <max_wheel_acceleration>10</max_wheel_acceleration>
          <!-- output -->
          <publish_odom>true</publish_odom>
          <publish_odom_tf>true</publish_odom_tf>
          <publish_wheel_tf>false</publish_wheel_tf>
          <odometry_frame>odom</odometry_frame>
          <robot_base_frame>base_link</robot_base_frame>
    </plugin>

    <plugin name="mickrobot_joint_state" filename="libgazebo_ros_joint_state_publisher.so">
      <ros>
        <remapping>~/out:=joint_states</remapping>
      </ros>
      <update_rate>30</update_rate>
      <joint_name>right_back_wheel_joint</joint_name>
      <joint_name>left_back_wheel_joint</joint_name>
    </plugin>    
  </gazebo> 

  <gazebo>
    <plugin name="diff_drive1" filename="libgazebo_ros_diff_drive.so">
      <ros>
        <namespace>/</namespace>
        <remapping>cmd_vel:=cmd_vel</remapping>
      </ros>
      <update_rate>30</update_rate>
      <left_joint>right_back_wheel_joint</left_joint>
      <right_joint>left_back_wheel_joint</right_joint>
      <wheel_separation>0.447</wheel_separation>
      <wheel_diameter>0.2032</wheel_diameter>
      <command_topic>cmd_vel</command_topic>
      <max_wheel_torque>50</max_wheel_torque>
      <max_wheel_acceleration>10</max_wheel_acceleration>
      <robot_base_frame>base_link</robot_base_frame>
    </plugin> 
  </gazebo>
  
  <!-- imu_plugin -->
  <gazebo reference="imu_link">
    <sensor name="imu_sensor" type="imu">
      <plugin filename="libgazebo_ros_imu_sensor.so" name="imu_plugin">
        <ros>
          <namespace>/</namespace>
          <remapping>~/out:=imu</remapping>
        </ros>
        <initial_orientation_as_reference>false</initial_orientation_as_reference>
      </plugin>
      <always_on>true</always_on>
      <update_rate>100</update_rate>
      <visualize>true</visualize>
      <imu>
        <angular_velocity>
          <x><noise type="none"/></x>
          <y><noise type="none"/></y>
          <z><noise type="none"/></z>
        </angular_velocity>
        <linear_acceleration>
          <x><noise type="none"/></x>
          <y><noise type="none"/></y>
          <z><noise type="none"/></z>
        </linear_acceleration>
      </imu>
    </sensor>
  </gazebo>
  
  <!-- camera_plugin -->
  <gazebo reference="camera_link">
    <sensor type="camera" name="camera_sensor">
      <always_on>true</always_on>
      <update_rate>30</update_rate>
      <camera>
        <horizontal_fov>1.047</horizontal_fov>
        <image>
          <width>640</width>
          <height>480</height>
          <format>R8G8B8</format>
        </image>
        <clip>
          <near>0.1</near>
          <far>100</far>
        </clip>
      </camera>
      <plugin name="gazebo_ros_camera" filename="libgazebo_ros_camera.so">
        <ros__parameters>
          <camera_name>camera</camera_name>
          <image_topic_name>image_raw</image_topic_name>
          <camera_info_topic_name>camera_info</camera_info_topic_name>
          <frame_name>camera_link</frame_name>
        </ros__parameters>
      </plugin>
    </sensor>
  </gazebo>
  
  <!-- gnss_plugin -->
  <gazebo reference="gnss_link">
    <sensor name="gnss_sensor" type="gps">
      <always_on>true</always_on>
      <pose>0.173 0.165 0.4 0 0 0</pose>
      <update_rate>5.0</update_rate>
      <plugin name="gazebo_ros_gps" filename="libgazebo_ros_gps_sensor.so">
        <verbose>true</verbose>
        <ros>
          <namespace>/sensors</namespace>
          <remapping>~/out:=gps</remapping>
          <publish_queue_size>100</publish_queue_size>
          <subscribe_queue_size>100</subscribe_queue_size>
        </ros>
        <frame_id>gnss_link</frame_id>
        <update_rate>5.0</update_rate>
        <velocity_topic>gps_velocity</velocity_topic>
        <reference_latitude>0</reference_latitude>
        <reference_longitude>0</reference_longitude>
        <reference_altitude>100.0</reference_altitude>
      </plugin>
    </sensor>
  </gazebo>

  <!--laser_plugin -->
  <gazebo reference="laser_link">
    <sensor name="laser_sensor" type="ray">
      <always_on>true</always_on>
      <visualize>true</visualize>
      <update_rate>5</update_rate>
      <pose>0.173 0.13 0.37 0 0 0</pose>
      <ray>
        <scan>
          <horizontal>
            <samples>360</samples>
            <resolution>1.000000</resolution>
            <min_angle>0.000000</min_angle>
            <max_angle>6.280000</max_angle>
          </horizontal>
        </scan>
        <range>
          <min>0.120000</min>
          <max>3.5</max>
          <resolution>0.015000</resolution>
        </range>
      </ray>
  
      <plugin name="laserscan" filename="libgazebo_ros_ray_sensor.so">
        <ros>
          <remapping>~/out:=scan</remapping>
        </ros>
        <output_type>sensor_msgs/LaserScan</output_type>
        <frame_name>laser_link</frame_name>
      </plugin>
    </sensor>
  </gazebo>
   
</robot>
