<?xml version="1.0"?>
<robot name="mickrobot" xmlns:xacro="http://ros.org/wiki/xacro">
  <link name="base_footprint">
    <visual>
      <geometry>
        <sphere radius="0.001" />  
      </geometry>
      <material name="invisible">
        <color rgba="0 0 0 0"/>  
      </material>
    </visual>
  </link>
<joint name="base_joint" type="fixed">
  <parent link="base_footprint"/>
  <child link="base_link"/>
  <!-- 假设 base_link 原点在车头，而几何中心在车辆后移 0.2 米且右移 0.1 米的位置 -->
  <origin xyz="0.0 0.0 0.0" rpy="0 0 0"/>
</joint>

  <!-- base -->
  <link name="base_link">
    <visual>
      <origin xyz="-0.3 -0.1665 0.0" rpy="0 0 0"/>
      <geometry>
        <mesh filename="package://mickrobot_description/urdf/mesh/mickx4_body.STL" scale="0.001 0.001 0.001"/>
      </geometry>
    </visual>

    <collision>
      <origin xyz="0.0 0.0 0.08" rpy="0 0 0"/>
      <geometry>
        <box size="0.6 0.333 0.16"/>
      </geometry>
    </collision>

    <inertial>
      <mass value="25"/>
      <origin xyz="0.0 0.0 0.08" rpy="0 0 0"/>
      <inertia 
        ixx="0.284" ixy="0" ixz="0"  
        iyy="0.803" iyz="0"           
        izz="0.981"/>
    </inertial>
  </link>

  
  <!-- right_back_wheel 0 -0.119 0.111-->
  <link   name="right_back_wheel">
    <visual>
      <origin xyz="0.12 0 -0.11" rpy="0 0 1.57079"/>
      <geometry>
        <mesh filename="package://mickrobot_description/urdf/mesh/mickx4_wheel_8inches_2.STL" scale="0.001 0.001 0.001"/>
      </geometry>
    </visual>

    <collision>
      <origin xyz="-0 0.035 0" rpy="0 1.57079 -1.57079"/>
      <geometry>
        <cylinder radius="0.1016" length="0.06"/>
      </geometry>
    </collision>
    
    <inertial>  
      <mass value="1"/>
      <origin xyz="-0. 0.035 0" rpy="0 1.57079 -1.57079"/>
      <inertia ixx="0.00288" ixy="0.0" ixz="0.0" iyy="0.00288" iyz="0.0" izz="0.00516"/>
    </inertial>
  </link>
 
  <joint   name="right_back_wheel_joint" type="continuous">
    <axis xyz="1 0 0"/>
    <parent   link="base_link"/>
    <child   link="right_back_wheel"/>
    <origin   xyz="-0.2 -0.26 0.0"/>
    <limit effort="100"   velocity="100"/>
  </joint>
  <!-- right_front_wheel -->
  <link   name="right_front_wheel">
    <visual>
      <origin xyz="0.12 0 -0.11" rpy="0 0 1.57079"/>
      <geometry>
        <mesh filename="package://mickrobot_description/urdf/mesh/mickx4_wheel_8inches_2.STL" scale="0.001 0.001 0.001"/>
      </geometry>
    </visual>

    <collision>
      <origin xyz="-0 0.035 0" rpy="0 1.57079 -1.57079"/>
      <geometry>
        <cylinder radius="0.1016" length="0.06"/>
      </geometry>
    </collision>
    
    <inertial>  
      <mass value="1"/>
      <origin xyz="-0. 0.035 0" rpy="0 1.57079 -1.57079"/>
      <inertia ixx="0.00288" ixy="0.0" ixz="0.0" iyy="0.00288" iyz="0.0" izz="0.00516"/>
    </inertial>
  </link>
 
  <joint   name="right_front_wheel_joint" type="continuous">
    <axis xyz="1 0 0"/>
    <parent   link="base_link"/>
    <child   link="right_front_wheel"/>
    <origin   xyz="0.2 -0.26 0.0"/>
    <limit effort="100"   velocity="100"/>
  </joint>
  <!-- left_back_wheel -->
  <link   name="left_back_wheel">
    <visual>
      <origin xyz="-0.12 0 -0.11" rpy="0 0 -1.57079"/>
      <geometry>
        <mesh filename="package://mickrobot_description/urdf/mesh/mickx4_wheel_8inches_2.STL" scale="0.001 0.001 0.001"/>
      </geometry>
    </visual>

    <collision>
      <origin xyz="0 -0.035 0" rpy="0 1.57079 -1.57079"/>
      <geometry>
        <cylinder radius="0.1016" length="0.06"/>
      </geometry>
    </collision>
    
    <inertial>  
      <mass value="1"/>
      <origin xyz="0 -0.035 0" rpy="0 1.57079 -1.57079"/>
      <inertia ixx="0.00288" ixy="0.0" ixz="0.0" iyy="0.00288" iyz="0.0" izz="0.00516"/>
    </inertial>
  </link>
 
  <joint   name="left_back_wheel_joint" type="continuous">
    <axis xyz="1 0 0"/>
    <parent   link="base_link"/>
    <child   link="left_back_wheel"/>
    <origin   xyz="-0.2 0.26 0.0"/>
    <limit effort="100"   velocity="100"/>
  </joint> 

  <!-- left_front_wheel -->
     <link   name="left_front_wheel">
    <visual>
      <origin xyz="-0.12 0 -0.11" rpy="0 0 -1.57079"/>
      <geometry>
        <mesh filename="package://mickrobot_description/urdf/mesh/mickx4_wheel_8inches_2.STL" scale="0.001 0.001 0.001"/>
      </geometry>
    </visual>

    <collision>
      <origin xyz="0 -0.035 0" rpy="0 1.57079 -1.57079"/>
      <geometry>
        <cylinder radius="0.1016" length="0.06"/>
      </geometry>
    </collision>
    
    <inertial>  
      <mass value="1"/>
      <origin xyz="0 -0.035 0" rpy="0 1.57079 -1.57079"/>
      <inertia ixx="0.00288" ixy="0.0" ixz="0.0" iyy="0.00288" iyz="0.0" izz="0.00516"/>
    </inertial>
  </link>
 
  <joint   name="left_front_wheel_joint" type="continuous">
    <axis xyz="1 0 0"/>
    <parent   link="base_link"/>
    <child   link="left_front_wheel"/>
    <origin   xyz="0.2 0.26 0.0"/>
    <limit effort="100"   velocity="100"/>
  </joint> 
 
 
  <!-- sensor -->
  <link   name="sensor_link">
    <visual>
      <origin xyz="0 0 0" rpy="0 0 0"/>
      <geometry>
        <mesh filename="package://mickrobot_description/urdf/mesh/mickx4_sensorkit1.STL" scale="0.001 0.001 0.001"/>
      </geometry>
    </visual>

    <collision>
      <origin xyz="0.12 0.12 0.1" rpy="0 0 0 "/>
      <geometry>
        <box size="0.09 0.12 0.20"/>
      </geometry>
    </collision>

    <inertial>
      <mass value="1"/>
      <origin xyz="0.12 0.12 0.05" rpy="0 0 0"/>
      <inertia ixx="0.00333" ixy="0.0" ixz="0.0" iyy="0.00333" iyz="0.0" izz="0.00240"/>
    </inertial>
  </link>
 
  <joint   name="sensor_joint" type="fixed">  
    <parent   link="base_link"/>
    <child   link="sensor_link"/>
    <origin   xyz="0.09 -0.1165 0.16"/>
  </joint>
  

  <link name="imu_link">
    <visual>
    <origin xyz="0 0 0.0" rpy="0 0 0"/>
    <geometry>
          <box size="0.07 0.07 0.02"/>
    </geometry>
  </visual>

  <collision>
    <origin xyz="0.0 0.0 0.0" rpy="0.0 0.0 0.0"/>
    <geometry>
      <box size="0.07 0.07 0.02"/>
    </geometry>
  </collision>

  <inertial>
    <origin xyz="0.0 0.0 0.0" rpy="0.0 0.0 0.0"/>
    <mass value="0.5"/>
    <inertia ixx="3.333e-5" ixy="0.0" ixz="0.0" iyy="3.333e-5" iyz="0.0" izz="3.333e-5"/>
  </inertial>
  
  </link>

  <joint name="imu_joint" type="fixed">
    <parent link="base_link" />
    <child link="imu_link" />
    <origin xyz="0.23 0.0 0.27" rpy="0.0 0.0 0.0" />
  </joint>

  <!-- gnss -->
  <link name="gnss_link">
    <visual>
      <origin xyz="0 0 0.0" rpy="0 0 0"/>
      <geometry>
        <box size="0.02 0.02 0.02"/>
      </geometry>
    </visual>

    <collision>
      <origin xyz="0.0 0.0 0.0" rpy="0.0 0.0 0.0"/>
      <geometry>
        <box size="0.02 0.02 0.02"/>
      </geometry>
    </collision>

    <inertial>
      <origin xyz="0.0 0.0 0.0" rpy="0.0 0.0 0.0"/>
      <mass value="0.5"/>
      <inertia ixx="3.333e-5" ixy="0.0" ixz="0.0" iyy="3.333e-5" iyz="0.0" izz="3.333e-5"/>
    </inertial>
  
  </link>

  <joint name="gnss_joint" type="fixed">
    <parent link="base_link" />
    <child link="gnss_link" />
    <origin xyz="0.235 0.0 0.42" rpy="0.0 0.0 0.0" />
  </joint>

  <link name="laser_link">
    <visual>
      <origin xyz="0 0 0" rpy="0 0 0"/>
      <geometry>
        <cylinder length="0.05" radius="0.04"/>
      </geometry>
    </visual>

    <collision>
      <origin xyz="0 0 0" rpy="0 0 0"/>
      <geometry>
        <cylinder length="0.05" radius="0.04"/>
      </geometry>
    </collision>

    <inertial>
      <mass value="0.1"/>
      <inertia ixx="6.083e-5" ixy="0" ixz="0" iyy="6.083e-5" iyz="0" izz="8.0e-5"/>
    </inertial>
  </link>
  
  <joint name="laser_joint" type="fixed">
      <parent link="base_link" />
      <child link="laser_link" />
      <origin xyz="0.23 0.0 0.38" />
  </joint>

  <!-- camera -->
  <link name="camera_link">
    <visual>
      <origin xyz="0 0 0" rpy="0 0 0"/>
      <geometry>
        <box size="0.02 0.09 0.03"/>
      </geometry>
    </visual>
    
    <inertial>
      <mass value="0.1"/>
      <origin xyz="0 0 0" rpy="0 0 0"/>
      <inertia ixx="6.083e-5" ixy="0" ixz="0" iyy="6.083e-5" iyz="0" izz="6.083e-5"/>
    </inertial>
       
    <collision>
      <origin xyz="0 0 0" rpy="0 0 0"/>
      <geometry>
        <box size="0.02 0.09 0.03"/>
      </geometry>
    </collision>
  </link>

  <joint name="camera_joint" type="fixed">
    <parent link="base_link"/>
    <child link="camera_link"/>
    <origin xyz="0.29 0.0 0.31" rpy="0 0 0"/>
  </joint>


</robot>
